
> `/src/pages/users/index.test.tsx`

```tsx
import { describe, expect, it } from 'vitest'  
import { UserResponse } from '@/type/user/response'  
import { fetchJson } from '@/utils/fetchUtils.ts'  
  
const fetchUser = async (): Promise<UserResponse> => {  
  try {  
    const data: UserResponse = await fetchJson<UserResponse>(`/users`) // 실제 API 호출  
    return data  
  } catch (error) {  
    console.error('Error fetching user detail:', error)  
    throw error // 에러를 던져서 useQuery에서 처리하게 함  
  }  
}  
  
describe('fetchUser', () => {  
  it('should fetch userList successfully from API', async () => {  
    const userList: UserResponse = await fetchUser() // 실제 API 호출  
  
    // 성공적인 API 호출 후 유저 리스트를 확인하는 부분  
    expect(userList).toBeDefined() // 데이터가 잘 반환되었는지 확인  
    expect(userList).toHaveProperty('users') // 예를 들어 'users' 속성이 존재하는지 체크  
    expect(Array.isArray(userList.users)).toBe(true) // 'users'가 배열인지 확인  
  
    expect(userList.users[0]).toHaveProperty('id') // 'id' 속성이 있는지 확인 (예시)  
    // expect(userList.users[0]).toHaveProperty('name') // 'name' 속성이 있는지 확인 (예시)  
    expect(userList.users[0]).toHaveProperty('username') // 'username' 속성이 있는지 확인 (예시)  
  })  
  
  it('should throw an error if the fetch fails', async () => {  
    const invalidFetchUser = async () => {  
      return fetchJson<UserResponse>('/invalid-url') // 잘못된 URL을 호출하여 실패하도록 설정  
    }  
  
    // 정상적으로 실패가 throw되고 오류메시지도 '데이터 조회 중 오류가 발생했습니다.'로 넘어와서 통과됨  
    await expect(invalidFetchUser()).rejects.toThrowError('데이터 조회 중 오류가 발생했습니다.') // 실제 오류 메시지 확인  
  })  
})
```

> 만약, `await expect(invalidFetchUser()).rejects.toThrowError()`에 전달하는 string 값이 잘못된 경우 아래처럼 된다.
![[유저리스트 조회 테스트 - await expect(invalidFetchUser()).rejects.toThrowError().png]]